Workbook

Sheet Summary
A1: Payment gateway reconciliation, 1-7 September 2026 (UTC, NAD)
A2: Every figure below is a formula on the other sheets. Change a row in Exceptions or the raw files and the bridge recalculates; the residual must stay 0.00.
A4: Bridge on gross amounts: internal total to gateway total | B4: NAD
A5: Internal SUCCESS deposits, total | B5: =SUMIFS('Internal deposits'!$D:$D,'Internal deposits'!$H:$H,"SUCCESS") -> 218280
A6: - Duplicate internal deposit rows | B6: =SUMIFS(Exceptions!$I$2:$I$50,Exceptions!$H$2:$H$50,A6) -> -1300
A7: - Reversals / chargebacks | B7: =SUMIFS(Exceptions!$I$2:$I$50,Exceptions!$H$2:$H$50,A7) -> -850
A8: - Deposits with no settlement yet (mid-week) | B8: =SUMIFS(Exceptions!$I$2:$I$50,Exceptions!$H$2:$H$50,A8) -> -2700
A9: - Created in the last 15 min, not yet settled (provisional) | B9: =SUMIFS(Exceptions!$I$2:$I$50,Exceptions!$H$2:$H$50,A9) -> -3650
A10: + Settled in the first 15 min, no deposit this week (provisional) | B10: =SUMIFS(Exceptions!$I$2:$I$50,Exceptions!$H$2:$H$50,A10) -> 2600
A11: + Settlements with no internal record | B11: =SUMIFS(Exceptions!$I$2:$I$50,Exceptions!$H$2:$H$50,A11) -> 2900
A12: + Settled by the gateway but marked FAILED by us | B12: =SUMIFS(Exceptions!$I$2:$I$50,Exceptions!$H$2:$H$50,A12) -> 250
A13: + Duplicate gateway settlement rows | B13: =SUMIFS(Exceptions!$I$2:$I$50,Exceptions!$H$2:$H$50,A13) -> 1550
A14: +/- Gross amount differences with the gateway (net) | B14: =SUMIFS(Exceptions!$I$2:$I$50,Exceptions!$H$2:$H$50,A14) -> 900
A15: +/- Rounding (exactly 1 cent) | B15: =SUMIFS(Exceptions!$I$2:$I$50,Exceptions!$H$2:$H$50,A15) -> -0.03
A16: Gateway total implied by the bridge | B16: =SUM(B5:B15) -> 217979.97
A17: Gateway SETTLED total, from the settlement file | B17: =SUMIFS('Gateway settlement'!$D:$D,'Gateway settlement'!$H:$H,"SETTLED") -> 217979.97
A18: Residual (unexplained): must be 0.00 | B18: =ROUND(B17-B16,2) -> 0
A20: Category | B20: Classification | C20: Rows | D20: Impact (NAD) | E20: What the impact means | F20: Owner
A21: BREAK: payment confirmed, wallet not credited | B21: Genuine break | C21: =COUNTIFS(Exceptions!$C$2:$C$50,A21) -> 2 | D21: =SUMIFS(Exceptions!$G$2:$G$50,Exceptions!$C$2:$C$50,A21) -> 250 | E21: Owed to the player | F21: Payments engineering
A22: BREAK: unrecognised settlement (no internal record) | B22: Genuine break | C22: =COUNTIFS(Exceptions!$C$2:$C$50,A22) -> 4 | D22: =SUMIFS(Exceptions!$G$2:$G$50,Exceptions!$C$2:$C$50,A22) -> 2900 | E22: Settled money not yet identified as ours | F22: Payments + Finance
A23: BREAK: net amount is not gross minus fee | B23: Genuine break | C23: =COUNTIFS(Exceptions!$C$2:$C$50,A23) -> 2 | D23: =SUMIFS(Exceptions!$G$2:$G$50,Exceptions!$C$2:$C$50,A23) -> 4 | E23: Short-paid by the gateway | F23: Finance
A24: BREAK: settled fee differs from contracted fee | B24: Genuine break | C24: =COUNTIFS(Exceptions!$C$2:$C$50,A24) -> 4 | D24: =SUMIFS(Exceptions!$G$2:$G$50,Exceptions!$C$2:$C$50,A24) -> 3.75 | E24: Fee overcharged by the gateway | F24: Finance
A25: BREAK: settled gross amount differs from internal amount | B25: Genuine break | C25: =COUNTIFS(Exceptions!$C$2:$C$50,A25) -> 4 | D25: =SUMIFS(Exceptions!$G$2:$G$50,Exceptions!$C$2:$C$50,A25) -> -900 | E25: Internal minus gateway (negative: player under-credited) | F25: Finance
A26: BREAK: duplicate gateway settlement for one reference (double-credit risk) | B26: Genuine break | C26: =COUNTIFS(Exceptions!$C$2:$C$50,A26) -> 4 | D26: =SUMIFS(Exceptions!$G$2:$G$50,Exceptions!$C$2:$C$50,A26) -> 0 | E26: 0 per row; exposure in the bridge | F26: Payments engineering
A27: BREAK: duplicate internal SUCCESS deposit for one settlement (double-credit risk) | B27: Genuine break | C27: =COUNTIFS(Exceptions!$C$2:$C$50,A27) -> 6 | D27: =SUMIFS(Exceptions!$G$2:$G$50,Exceptions!$C$2:$C$50,A27) -> 0 | E27: 0 per row; exposure in the bridge | F27: Engineering
A28: REVERSAL: gateway reversed/charged back after settlement | B28: Genuine break | C28: =COUNTIFS(Exceptions!$C$2:$C$50,A28) -> 3 | D28: =SUMIFS(Exceptions!$G$2:$G$50,Exceptions!$C$2:$C$50,A28) -> 850 | E28: Reversed amount to claw back | F28: Finance
A29: BREAK: deposit SUCCESS, no gateway settlement found | B29: Genuine break | C29: =COUNTIFS(Exceptions!$C$2:$C$50,A29) -> 5 | D29: =SUMIFS(Exceptions!$G$2:$G$50,Exceptions!$C$2:$C$50,A29) -> 2700 | E29: Credited to the player, no money received yet | F29: Finance
A30: TIMING: settlement expected in next period (created near cut-off) | B30: Timing difference | C30: =COUNTIFS(Exceptions!$C$2:$C$50,A30) -> 3 | D30: =SUMIFS(Exceptions!$G$2:$G$50,Exceptions!$C$2:$C$50,A30) -> 3650 | E30: Awaiting settlement next period | F30: Finance
A31: TIMING: prior-period deposit settled at start of period | B31: Timing difference | C31: =COUNTIFS(Exceptions!$C$2:$C$50,A31) -> 3 | D31: =SUMIFS(Exceptions!$G$2:$G$50,Exceptions!$C$2:$C$50,A31) -> 2600 | E31: Awaiting match to last period's deposit | F31: Finance
A32: NOT A PROBLEM: rounding difference <= 1 cent | B32: Not a problem | C32: =COUNTIFS(Exceptions!$C$2:$C$50,A32) -> 3 | D32: =SUMIFS(Exceptions!$G$2:$G$50,Exceptions!$C$2:$C$50,A32) -> 0.03 | E32: Internal minus gateway | F32: Finance
A33: NOT A PROBLEM: reference formatting differs (matched after normalising) | B33: Not a problem | C33: =COUNTIFS(Exceptions!$C$2:$C$50,A33) -> 6 | D33: =SUMIFS(Exceptions!$G$2:$G$50,Exceptions!$C$2:$C$50,A33) -> 0 | E33: None | F33: Payments engineering
A34: Total listed differences | C34: =SUM(C21:C33) -> 49
A36: Classification | B36: Rows
A37: Genuine break | B37: =COUNTIFS(Exceptions!$B$2:$B$50,A37) -> 34
A38: Timing difference | B38: =COUNTIFS(Exceptions!$B$2:$B$50,A38) -> 6
A39: Not a problem | B39: =COUNTIFS(Exceptions!$B$2:$B$50,A39) -> 9

Sheet Assumptions
A1: Topic | B1: Assumption
A2: Period | B2: 2026-09-01 00:00:00 to 2026-09-07 23:59:59 UTC inclusive. All timestamps are UTC; both files are NAD only (checked).
A3: Totals compared | B3: Internal total = SUCCESS deposits only (only SUCCESS credits a wallet). Gateway total = SETTLED rows only; REVERSED rows are listed as reversals.
A4: Matching key | B4: Our gateway_ref = the gateway's merchant_ref after upper-casing and removing everything but letters and digits. 6 references differ only in formatting and are listed as 'not a problem'.
A5: Fee rule | B5: Contract fee = ROUND(2% x gross + 1.00, 2). Any fee or net difference of 1 cent or more is a break.
A6: Rounding | B6: A gross difference of exactly 1 cent is treated as rounding (immaterial); 2 cents or more is a break. This is a materiality choice for Finance to confirm.
A7: Cut-off window | B7: A SUCCESS deposit created in the last 15 minutes with no settlement, and a settlement in the first 15 minutes whose reference is not in this period's deposits, are timing differences. They are provisional until matched in the adjacent weeks' files.
A8: Settlement lag | B8: Matched settlements arrive 28 min after the deposit (median), 50 min at most. The nearest unexplained items to either boundary are 2 hours or more away (the 5 unsettled deposits 15+ hours before period end; the earliest unrecognised settlement 2 hours after the start), so the classification does not depend on the exact cut-off window.
A9: Reversals | B9: A REVERSED row means the gateway pulled the money back after settling. Treated as a genuine break until the matching wallet debit is confirmed; wallet postings are not in these files.
A10: Duplicates | B10: Two SUCCESS deposits for one reference created seconds apart = one payment recorded twice; the later is the duplicate. Two settlement rows with the same gateway_txn_id = one transaction reported twice; the later is the duplicate.
A11: Bridge basis | B11: The bridge is on gross amounts, which is what deposits record. Fee and net differences do not move gross, so they are actions, not bridge lines.
A12: Not listed | B12: FAILED deposits with no settlement agree on both sides (nothing paid, nothing settled), so they are not differences.

Sheet Exceptions
A1: exception_id | B1: classification | C1: category | D1: explanation | E1: next_step | F1: owner | G1: financial_impact | H1: bridge_line | I1: bridge_amount | J1: deposit_id | K1: player_id | L1: created_at | M1: dep_amount | N1: gateway_ref | O1: gateway_txn_id | P1: merchant_ref | Q1: settled_at | R1: gross_amount | S1: fee | T1: expected_fee | U1: net_amount | V1: gw_status
A2: E001 | B2: Genuine break | C2: BREAK: deposit SUCCESS, no gateway settlement found | D2: D000055 for 150.00, created 2026-09-02 06:58:04, is SUCCESS on our side but has no settlement 137 h later at period end, far beyond the longest settlement lag seen this week (50 min). | E2: Re-check the next settlement file; escalate to the gateway if still missing after 3 days | F2: Finance | G2: 150 | H2: - Deposits with no settlement yet (mid-week) | I2: -150 | J2: D000055 | K2: P0081 | L2: 2026-09-02 06:58:04 | M2: 150 | N2: GW-000055
A3: E002 | B3: Genuine break | C3: BREAK: deposit SUCCESS, no gateway settlement found | D3: D000125 for 1,000.00, created 2026-09-04 05:36:49, is SUCCESS on our side but has no settlement 90 h later at period end, far beyond the longest settlement lag seen this week (50 min). | E3: Re-check the next settlement file; escalate to the gateway if still missing after 3 days | F3: Finance | G3: 1000 | H3: - Deposits with no settlement yet (mid-week) | I3: -1000 | J3: D000125 | K3: P0039 | L3: 2026-09-04 05:36:49 | M3: 1000 | N3: GW-000125
A4: E003 | B4: Genuine break | C4: BREAK: deposit SUCCESS, no gateway settlement found | D4: D000182 for 500.00, created 2026-09-05 19:41:52, is SUCCESS on our side but has no settlement 52 h later at period end, far beyond the longest settlement lag seen this week (50 min). | E4: Re-check the next settlement file; escalate to the gateway if still missing after 3 days | F4: Finance | G4: 500 | H4: - Deposits with no settlement yet (mid-week) | I4: -500 | J4: D000182 | K4: P0033 | L4: 2026-09-05 19:41:52 | M4: 500 | N4: GW-000182
A5: E004 | B5: Genuine break | C5: BREAK: deposit SUCCESS, no gateway settlement found | D5: D000218 for 50.00, created 2026-09-06 12:49:57, is SUCCESS on our side but has no settlement 35 h later at period end, far beyond the longest settlement lag seen this week (50 min). | E5: Re-check the next settlement file; escalate to the gateway if still missing after 3 days | F5: Finance | G5: 50 | H5: - Deposits with no settlement yet (mid-week) | I5: -50 | J5: D000218 | K5: P0034 | L5: 2026-09-06 12:49:57 | M5: 50 | N5: GW-000218
A6: E005 | B6: Genuine break | C6: BREAK: deposit SUCCESS, no gateway settlement found | D6: D000269 for 1,000.00, created 2026-09-07 08:48:58, is SUCCESS on our side but has no settlement 15 h later at period end, far beyond the longest settlement lag seen this week (50 min). | E6: Re-check the next settlement file; escalate to the gateway if still missing after 3 days | F6: Finance | G6: 1000 | H6: - Deposits with no settlement yet (mid-week) | I6: -1000 | J6: D000269 | K6: P0036 | L6: 2026-09-07 08:48:58 | M6: 1000 | N6: GW-000269
A7: E006 | B7: Genuine break | C7: BREAK: duplicate gateway settlement for one reference (double-credit risk) | D7: GT900164 for GW-000164 appears 2 times in the settlement file (settled 2026-09-05 05:39:45, 2026-09-05 10:39:45). This row is the original. | E7: Confirm with the gateway whether money moved twice or only the report repeated | F7: Payments engineering | G7: 0 | H7: + Duplicate gateway settlement rows | I7: 0 | J7: D000164 | K7: P0059 | L7: 2026-09-05 05:15:45 | M7: 1500 | N7: GW-000164 | O7: GT900164 | P7: GW-000164 | Q7: 2026-09-05 05:39:45 | R7: 1500 | S7: 31 | T7: 31 | U7: 1469 | V7: SETTLED
A8: E007 | B8: Genuine break | C8: BREAK: duplicate gateway settlement for one reference (double-credit risk) | D8: GT900164 for GW-000164 appears 2 times in the settlement file (settled 2026-09-05 05:39:45, 2026-09-05 10:39:45). This row is the repeat: it adds 1,500.00 to the gateway total without a second deposit. | E8: Confirm with the gateway whether money moved twice or only the report repeated | F8: Payments engineering | G8: 0 | H8: + Duplicate gateway settlement rows | I8: 1500 | J8: D000164 | K8: P0059 | L8: 2026-09-05 05:15:45 | M8: 1500 | N8: GW-000164 | O8: GT900164 | P8: GW-000164 | Q8: 2026-09-05 10:39:45 | R8: 1500 | S8: 31 | T8: 31 | U8: 1469 | V8: SETTLED
A9: E008 | B9: Genuine break | C9: BREAK: duplicate gateway settlement for one reference (double-credit risk) | D9: GT900223 for GW-000223 appears 2 times in the settlement file (settled 2026-09-06 14:23:24, 2026-09-06 19:23:24). This row is the original. | E9: Confirm with the gateway whether money moved twice or only the report repeated | F9: Payments engineering | G9: 0 | H9: + Duplicate gateway settlement rows | I9: 0 | J9: D000223 | K9: P0046 | L9: 2026-09-06 13:38:24 | M9: 50 | N9: GW-000223 | O9: GT900223 | P9: GW-000223 | Q9: 2026-09-06 14:23:24 | R9: 50 | S9: 2 | T9: 2 | U9: 48 | V9: SETTLED
A10: E009 | B10: Genuine break | C10: BREAK: duplicate gateway settlement for one reference (double-credit risk) | D10: GT900223 for GW-000223 appears 2 times in the settlement file (settled 2026-09-06 14:23:24, 2026-09-06 19:23:24). This row is the repeat: it adds 50.00 to the gateway total without a second deposit. | E10: Confirm with the gateway whether money moved twice or only the report repeated | F10: Payments engineering | G10: 0 | H10: + Duplicate gateway settlement rows | I10: 50 | J10: D000223 | K10: P0046 | L10: 2026-09-06 13:38:24 | M10: 50 | N10: GW-000223 | O10: GT900223 | P10: GW-000223 | Q10: 2026-09-06 19:23:24 | R10: 50 | S10: 2 | T10: 2 | U10: 48 | V10: SETTLED
A11: E010 | B11: Genuine break | C11: BREAK: duplicate internal SUCCESS deposit for one settlement (double-credit risk) | D11: D000047 and D000325 are both SUCCESS for reference GW-000047, created 40 s apart, but the gateway settled once (1,000.00). This row is the original. | E11: Check whether the wallet was credited twice and reverse the extra credit; add an idempotency key | F11: Engineering | G11: 0 | H11: - Duplicate internal deposit rows | I11: 0 | J11: D000047 | K11: P0049 | L11: 2026-09-02 04:09:18 | M11: 1000 | N11: GW-000047 | O11: GT900047 | P11: GW-000047 | Q11: 2026-09-02 04:44:18 | R11: 1000 | S11: 21 | T11: 21 | U11: 979 | V11: SETTLED
A12: E011 | B12: Genuine break | C12: BREAK: duplicate internal SUCCESS deposit for one settlement (double-credit risk) | D12: D000047 and D000325 are both SUCCESS for reference GW-000047, created 40 s apart, but the gateway settled once (1,000.00). This row is the repeat. Only SUCCESS deposits credit a wallet, so the player was credited 1,000.00 twice for one payment: 1,000.00 with no money behind it. | E12: Check whether the wallet was credited twice and reverse the extra credit; add an idempotency key | F12: Engineering | G12: 0 | H12: - Duplicate internal deposit rows | I12: -1000 | J12: D000325 | K12: P0049 | L12: 2026-09-02 04:09:58 | M12: 1000 | N12: GW-000047 | O12: GT900047 | P12: GW-000047 | Q12: 2026-09-02 04:44:18 | R12: 1000 | S12: 21 | T12: 21 | U12: 979 | V12: SETTLED
A13: E012 | B13: Genuine break | C13: BREAK: duplicate internal SUCCESS deposit for one settlement (double-credit risk) | D13: D000140 and D000326 are both SUCCESS for reference GW-000140, created 40 s apart, but the gateway settled once (150.00). This row is the original. | E13: Check whether the wallet was credited twice and reverse the extra credit; add an idempotency key | F13: Engineering | G13: 0 | H13: - Duplicate internal deposit rows | I13: 0 | J13: D000140 | K13: P0020 | L13: 2026-09-04 13:44:33 | M13: 150 | N13: GW-000140 | O13: GT900140 | P13: GW-000140 | Q13: 2026-09-04 14:23:33 | R13: 150 | S13: 4 | T13: 4 | U13: 146 | V13: SETTLED
A14: E013 | B14: Genuine break | C14: BREAK: duplicate internal SUCCESS deposit for one settlement (double-credit risk) | D14: D000140 and D000326 are both SUCCESS for reference GW-000140, created 40 s apart, but the gateway settled once (150.00). This row is the repeat. Only SUCCESS deposits credit a wallet, so the player was credited 150.00 twice for one payment: 150.00 with no money behind it. | E14: Check whether the wallet was credited twice and reverse the extra credit; add an idempotency key | F14: Engineering | G14: 0 | H14: - Duplicate internal deposit rows | I14: -150 | J14: D000326 | K14: P0020 | L14: 2026-09-04 13:45:13 | M14: 150 | N14: GW-000140 | O14: GT900140 | P14: GW-000140 | Q14: 2026-09-04 14:23:33 | R14: 150 | S14: 4 | T14: 4 | U14: 146 | V14: SETTLED
A15: E014 | B15: Genuine break | C15: BREAK: duplicate internal SUCCESS deposit for one settlement (double-credit risk) | D15: D000168 and D000327 are both SUCCESS for reference GW-000168, created 40 s apart, but the gateway settled once (150.00). This row is the original. | E15: Check whether the wallet was credited twice and reverse the extra credit; add an idempotency key | F15: Engineering | G15: 0 | H15: - Duplicate internal deposit rows | I15: 0 | J15: D000168 | K15: P0015 | L15: 2026-09-05 06:56:09 | M15: 150 | N15: GW-000168 | O15: GT900168 | P15: GW-000168 | Q15: 2026-09-05 07:45:09 | R15: 150 | S15: 4 | T15: 4 | U15: 146 | V15: SETTLED
A16: E015 | B16: Genuine break | C16: BREAK: duplicate internal SUCCESS deposit for one settlement (double-credit risk) | D16: D000168 and D000327 are both SUCCESS for reference GW-000168, created 40 s apart, but the gateway settled once (150.00). This row is the repeat. Only SUCCESS deposits credit a wallet, so the player was credited 150.00 twice for one payment: 150.00 with no money behind it. | E16: Check whether the wallet was credited twice and reverse the extra credit; add an idempotency key | F16: Engineering | G16: 0 | H16: - Duplicate internal deposit rows | I16: -150 | J16: D000327 | K16: P0015 | L16: 2026-09-05 06:56:49 | M16: 150 | N16: GW-000168 | O16: GT900168 | P16: GW-000168 | Q16: 2026-09-05 07:45:09 | R16: 150 | S16: 4 | T16: 4 | U16: 146 | V16: SETTLED
A17: E016 | B17: Genuine break | C17: BREAK: net amount is not gross minus fee | D17: Net 977.00 is not gross 1,000.00 minus fee 21.00 = 979.00. Short-paid by 2.00. | E17: Claim the short-paid amount; ask the gateway how net was calculated | F17: Finance | G17: 2 | I17: 0 | J17: D000133 | K17: P0081 | L17: 2026-09-04 11:39:53 | M17: 1000 | N17: GW-000133 | O17: GT900133 | P17: GW-000133 | Q17: 2026-09-04 11:46:53 | R17: 1000 | S17: 21 | T17: 21 | U17: 977 | V17: SETTLED
A18: E017 | B18: Genuine break | C18: BREAK: net amount is not gross minus fee | D18: Net 487.00 is not gross 500.00 minus fee 11.00 = 489.00. Short-paid by 2.00. | E18: Claim the short-paid amount; ask the gateway how net was calculated | F18: Finance | G18: 2 | I18: 0 | J18: D000289 | K18: P0072 | L18: 2026-09-07 18:22:09 | M18: 500 | N18: GW-000289 | O18: GT900289 | P18: GW-000289 | Q18: 2026-09-07 18:42:09 | R18: 500 | S18: 11 | T18: 11 | U18: 487 | V18: SETTLED
A19: E018 | B19: Genuine break | C19: BREAK: payment confirmed, wallet not credited | D19: We marked D000306 FAILED, but the gateway settled 150.00 for GW-000306 (GT900306) at 2026-09-02 08:52:23. The player paid and was not credited: we owe 150.00. | E19: Credit the player's wallet today; check the callback/webhook logs for the lost confirmation | F19: Payments engineering | G19: 150 | H19: + Settled by the gateway but marked FAILED by us | I19: 150 | J19: D000306 | K19: P0071 | L19: 2026-09-02 08:43:23 | M19: 150 | N19: GW-000306 | O19: GT900306 | P19: GW-000306 | Q19: 2026-09-02 08:52:23 | R19: 150 | S19: 4 | T19: 4 | U19: 146 | V19: SETTLED
A20: E019 | B20: Genuine break | C20: BREAK: payment confirmed, wallet not credited | D20: We marked D000305 FAILED, but the gateway settled 100.00 for GW-000305 (GT900305) at 2026-09-06 02:41:57. The player paid and was not credited: we owe 100.00. | E20: Credit the player's wallet today; check the callback/webhook logs for the lost confirmation | F20: Payments engineering | G20: 100 | H20: + Settled by the gateway but marked FAILED by us | I20: 100 | J20: D000305 | K20: P0083 | L20: 2026-09-06 02:32:57 | M20: 100 | N20: GW-000305 | O20: GT900305 | P20: GW-000305 | Q20: 2026-09-06 02:41:57 | R20: 100 | S20: 3 | T20: 3 | U20: 97 | V20: SETTLED
A21: E020 | B21: Genuine break | C21: BREAK: settled fee differs from contracted fee | D21: Fee 6.00 vs contract 5.00 (2% of 200.00 + 1.00). Overcharged 1.00. | E21: Raise a fee dispute citing the contract (2% of gross + 1.00) | F21: Finance | G21: 1 | I21: 0 | J21: D000022 | K21: P0003 | L21: 2026-09-01 13:00:28 | M21: 200 | N21: GW-000022 | O21: GT900022 | P21: GW-000022 | Q21: 2026-09-01 13:02:28 | R21: 200 | S21: 6 | T21: 5 | U21: 194 | V21: SETTLED
A22: E021 | B22: Genuine break | C22: BREAK: settled fee differs from contracted fee | D22: Fee 4.75 vs contract 4.00 (2% of 150.00 + 1.00). Overcharged 0.75. | E22: Raise a fee dispute citing the contract (2% of gross + 1.00) | F22: Finance | G22: 0.75 | I22: 0 | J22: D000134 | K22: P0004 | L22: 2026-09-04 11:46:12 | M22: 150 | N22: GW-000134 | O22: GT900134 | P22: GW-000134 | Q22: 2026-09-04 12:16:12 | R22: 150 | S22: 4.75 | T22: 4 | U22: 145.25 | V22: SETTLED
A23: E022 | B23: Genuine break | C23: BREAK: settled fee differs from contracted fee | D23: Fee 3.50 vs contract 3.00 (2% of 100.00 + 1.00). Overcharged 0.50. | E23: Raise a fee dispute citing the contract (2% of gross + 1.00) | F23: Finance | G23: 0.5 | I23: 0 | J23: D000219 | K23: P0068 | L23: 2026-09-06 13:03:05 | M23: 100 | N23: GW-000219 | O23: GT900219 | P23: GW-000219 | Q23: 2026-09-06 13:21:05 | R23: 100 | S23: 3.5 | T23: 3 | U23: 96.5 | V23: SETTLED
A24: E023 | B24: Genuine break | C24: BREAK: settled fee differs from contracted fee | D24: Fee 8.50 vs contract 7.00 (2% of 300.00 + 1.00). Overcharged 1.50. | E24: Raise a fee dispute citing the contract (2% of gross + 1.00) | F24: Finance | G24: 1.5 | I24: 0 | J24: D000275 | K24: P0052 | L24: 2026-09-07 12:48:51 | M24: 300 | N24: GW-000275 | O24: GT900275 | P24: GW-000275 | Q24: 2026-09-07 13:03:51 | R24: 300 | S24: 8.5 | T24: 7 | U24: 291.5 | V24: SETTLED
A25: E024 | B25: Genuine break | C25: BREAK: settled gross amount differs from internal amount | D25: We recorded 100.00; the gateway settled 50.00 (-50.00): we credited 50.00 more than the gateway settled (over-credited). | E25: Dispute with the gateway using the payment evidence; correct the wallet once agreed | F25: Finance | G25: 50 | H25: +/- Gross amount differences with the gateway (net) | I25: -50 | J25: D000048 | K25: P0066 | L25: 2026-09-02 04:33:34 | M25: 100 | N25: GW-000048 | O25: GT900048 | P25: GW-000048 | Q25: 2026-09-02 04:40:34 | R25: 50 | S25: 2 | T25: 2 | U25: 48 | V25: SETTLED
A26: E025 | B26: Genuine break | C26: BREAK: settled gross amount differs from internal amount | D26: We recorded 5,000.00; the gateway settled 5,100.00 (+100.00): the player paid 100.00 more than we credited (under-credited). | E26: Dispute with the gateway using the payment evidence; correct the wallet once agreed | F26: Finance | G26: -100 | H26: +/- Gross amount differences with the gateway (net) | I26: 100 | J26: D000056 | K26: P0055 | L26: 2026-09-02 07:57:01 | M26: 5000 | N26: GW-000056 | O26: GT900056 | P26: GW-000056 | Q26: 2026-09-02 08:20:01 | R26: 5100 | S26: 103 | T26: 103 | U26: 4997 | V26: SETTLED
A27: E026 | B27: Genuine break | C27: BREAK: settled gross amount differs from internal amount | D27: We recorded 200.00; the gateway settled 1,000.00 (+800.00): the player paid 800.00 more than we credited (under-credited). | E27: Dispute with the gateway using the payment evidence; correct the wallet once agreed | F27: Finance | G27: -800 | H27: +/- Gross amount differences with the gateway (net) | I27: 800 | J27: D000064 | K27: P0017 | L27: 2026-09-02 11:49:56 | M27: 200 | N27: GW-000064 | O27: GT900064 | P27: GW-000064 | Q27: 2026-09-02 11:56:56 | R27: 1000 | S27: 21 | T27: 21 | U27: 979 | V27: SETTLED
A28: E027 | B28: Genuine break | C28: BREAK: settled gross amount differs from internal amount | D28: We recorded 200.00; the gateway settled 250.00 (+50.00): the player paid 50.00 more than we credited (under-credited). | E28: Dispute with the gateway using the payment evidence; correct the wallet once agreed | F28: Finance | G28: -50 | H28: +/- Gross amount differences with the gateway (net) | I28: 50 | J28: D000116 | K28: P0061 | L28: 2026-09-04 01:15:30 | M28: 200 | N28: GW-000116 | O28: GT900116 | P28: GW-000116 | Q28: 2026-09-04 01:58:30 | R28: 250 | S28: 6 | T28: 6 | U28: 244 | V28: SETTLED
A29: E028 | B29: Genuine break | C29: BREAK: unrecognised settlement (no internal record) | D29: The gateway settled 100.00 for GW-000302 (GT900302) at 2026-09-01 02:00:06, 2 h into the period, too late to be a prior-period deposit (longest lag 50 min). No deposit on our side carries this reference, not even a failed one. | E29: Ask the gateway for the transaction detail (payer, time, reference) before treating it as ours | F29: Payments + Finance | G29: 100 | H29: + Settlements with no internal record | I29: 100 | N29: GW-000302 | O29: GT900302 | P29: GW-000302 | Q29: 2026-09-01 02:00:06 | R29: 100 | S29: 3 | T29: 3 | U29: 97 | V29: SETTLED
A30: E029 | B30: Genuine break | C30: BREAK: unrecognised settlement (no internal record) | D30: The gateway settled 500.00 for GW-000303 (GT900303) at 2026-09-01 20:19:01, 20 h into the period, too late to be a prior-period deposit (longest lag 50 min). No deposit on our side carries this reference, not even a failed one. | E30: Ask the gateway for the transaction detail (payer, time, reference) before treating it as ours | F30: Payments + Finance | G30: 500 | H30: + Settlements with no internal record | I30: 500 | N30: GW-000303 | O30: GT900303 | P30: GW-000303 | Q30: 2026-09-01 20:19:01 | R30: 500 | S30: 11 | T30: 11 | U30: 489 | V30: SETTLED
A31: E030 | B31: Genuine break | C31: BREAK: unrecognised settlement (no internal record) | D31: The gateway settled 2,000.00 for GW-000304 (GT900304) at 2026-09-02 20:53:20, 45 h into the period, too late to be a prior-period deposit (longest lag 50 min). No deposit on our side carries this reference, not even a failed one. | E31: Ask the gateway for the transaction detail (payer, time, reference) before treating it as ours | F31: Payments + Finance | G31: 2000 | H31: + Settlements with no internal record | I31: 2000 | N31: GW-000304 | O31: GT900304 | P31: GW-000304 | Q31: 2026-09-02 20:53:20 | R31: 2000 | S31: 41 | T31: 41 | U31: 1959 | V31: SETTLED
A32: E031 | B32: Genuine break | C32: BREAK: unrecognised settlement (no internal record) | D32: The gateway settled 300.00 for GW-000301 (GT900301) at 2026-09-04 22:33:18, 95 h into the period, too late to be a prior-period deposit (longest lag 50 min). No deposit on our side carries this reference, not even a failed one. | E32: Ask the gateway for the transaction detail (payer, time, reference) before treating it as ours | F32: Payments + Finance | G32: 300 | H32: + Settlements with no internal record | I32: 300 | N32: GW-000301 | O32: GT900301 | P32: GW-000301 | Q32: 2026-09-04 22:33:18 | R32: 300 | S32: 7 | T32: 7 | U32: 293 | V32: SETTLED
A33: E032 | B33: Genuine break | C33: REVERSAL: gateway reversed/charged back after settlement | D33: The gateway reversed 500.00 (settlement row GT900097, settled_at 2026-09-03 10:20:08, status REVERSED, e.g. a chargeback). D000097 is still SUCCESS on our side and credited the wallet, so unless a matching debit was posted we are 500.00 out. | E33: Confirm the matching wallet debit was posted; if not, claw back | F33: Finance | G33: 500 | H33: - Reversals / chargebacks | I33: -500 | J33: D000097 | K33: P0008 | L33: 2026-09-03 09:54:08 | M33: 500 | N33: GW-000097 | O33: GT900097 | P33: GW-000097 | Q33: 2026-09-03 10:20:08 | R33: 500 | S33: 11 | T33: 11 | U33: 489 | V33: REVERSED
A34: E033 | B34: Genuine break | C34: REVERSAL: gateway reversed/charged back after settlement | D34: The gateway reversed 250.00 (settlement row GT900124, settled_at 2026-09-04 05:35:42, status REVERSED, e.g. a chargeback). D000124 is still SUCCESS on our side and credited the wallet, so unless a matching debit was posted we are 250.00 out. | E34: Confirm the matching wallet debit was posted; if not, claw back | F34: Finance | G34: 250 | H34: - Reversals / chargebacks | I34: -250 | J34: D000124 | K34: P0066 | L34: 2026-09-04 04:48:42 | M34: 250 | N34: GW-000124 | O34: GT900124 | P34: GW-000124 | Q34: 2026-09-04 05:35:42 | R34: 250 | S34: 6 | T34: 6 | U34: 244 | V34: REVERSED
A35: E034 | B35: Genuine break | C35: REVERSAL: gateway reversed/charged back after settlement | D35: The gateway reversed 100.00 (settlement row GT900273, settled_at 2026-09-07 11:55:02, status REVERSED, e.g. a chargeback). D000273 is still SUCCESS on our side and credited the wallet, so unless a matching debit was posted we are 100.00 out. | E35: Confirm the matching wallet debit was posted; if not, claw back | F35: Finance | G35: 100 | H35: - Reversals / chargebacks | I35: -100 | J35: D000273 | K35: P0014 | L35: 2026-09-07 11:15:02 | M35: 100 | N35: GW-000273 | O35: GT900273 | P35: GW-000273 | Q35: 2026-09-07 11:55:02 | R35: 100 | S35: 3 | T35: 3 | U35: 97 | V35: REVERSED
A36: E035 | B36: Timing difference | C36: TIMING: prior-period deposit settled at start of period | D36: The gateway settled 2,000.00 for GW-000331 at 2026-09-01 00:04:00, 4 min into the period. The reference is not in this week's deposits: most likely a deposit created just before midnight on 31 Aug (provisional until matched in last week's file). | E36: Match against the 25-31 Aug internal file; if missing, reclassify as unrecognised | F36: Finance | G36: 2000 | H36: + Settled in the first 15 min, no deposit this week (provisional) | I36: 2000 | N36: GW-000331 | O36: GT900331 | P36: GW-000331 | Q36: 2026-09-01 00:04:00 | R36: 2000 | S36: 41 | T36: 41 | U36: 1959 | V36: SETTLED
A37: E036 | B37: Timing difference | C37: TIMING: prior-period deposit settled at start of period | D37: The gateway settled 100.00 for GW-000332 at 2026-09-01 00:05:00, 5 min into the period. The reference is not in this week's deposits: most likely a deposit created just before midnight on 31 Aug (provisional until matched in last week's file). | E37: Match against the 25-31 Aug internal file; if missing, reclassify as unrecognised | F37: Finance | G37: 100 | H37: + Settled in the first 15 min, no deposit this week (provisional) | I37: 100 | N37: GW-000332 | O37: GT900332 | P37: GW-000332 | Q37: 2026-09-01 00:05:00 | R37: 100 | S37: 3 | T37: 3 | U37: 97 | V37: SETTLED
A38: E037 | B38: Timing difference | C38: TIMING: prior-period deposit settled at start of period | D38: The gateway settled 500.00 for GW-000333 at 2026-09-01 00:06:00, 6 min into the period. The reference is not in this week's deposits: most likely a deposit created just before midnight on 31 Aug (provisional until matched in last week's file). | E38: Match against the 25-31 Aug internal file; if missing, reclassify as unrecognised | F38: Finance | G38: 500 | H38: + Settled in the first 15 min, no deposit this week (provisional) | I38: 500 | N38: GW-000333 | O38: GT900333 | P38: GW-000333 | Q38: 2026-09-01 00:06:00 | R38: 500 | S38: 11 | T38: 11 | U38: 489 | V38: SETTLED
A39: E038 | B39: Timing difference | C39: TIMING: settlement expected in next period (created near cut-off) | D39: D000328 for 2,000.00 was created at 2026-09-07 23:54:00, 6 min before the period cut-off. With a median settlement lag of 28 min, it should settle in next week's file (provisional until matched). | E39: Match against the 8-14 Sep settlement file; if missing, reclassify as a break | F39: Finance | G39: 2000 | H39: - Created in the last 15 min, not yet settled (provisional) | I39: -2000 | J39: D000328 | K39: P0038 | L39: 2026-09-07 23:54:00 | M39: 2000 | N39: GW-000328
A40: E039 | B40: Timing difference | C40: TIMING: settlement expected in next period (created near cut-off) | D40: D000329 for 1,500.00 was created at 2026-09-07 23:54:30, 5 min before the period cut-off. With a median settlement lag of 28 min, it should settle in next week's file (provisional until matched). | E40: Match against the 8-14 Sep settlement file; if missing, reclassify as a break | F40: Finance | G40: 1500 | H40: - Created in the last 15 min, not yet settled (provisional) | I40: -1500 | J40: D000329 | K40: P0034 | L40: 2026-09-07 23:54:30 | M40: 1500 | N40: GW-000329
...

Sheet Internal deposits
A1: deposit_id | B1: player_id | C1: created_at | D1: amount | E1: currency | F1: method | G1: gateway_ref | H1: status
A2: D000001 | B2: P0077 | C2: 2026-09-01 00:03:44 | D2: 150 | E2: NAD | F2: EFT_INSTANT | G2: GW-000001 | H2: SUCCESS
A3: D000002 | B3: P0087 | C3: 2026-09-01 00:44:17 | D3: 1500 | E3: NAD | F3: EFT_INSTANT | G3: GW-000002 | H3: SUCCESS
A4: D000003 | B4: P0065 | C4: 2026-09-01 01:25:44 | D4: 500 | E4: NAD | F4: EFT_INSTANT | G4: GW-000003 | H4: SUCCESS
A5: D000004 | B5: P0050 | C5: 2026-09-01 01:29:40 | D5: 250 | E5: NAD | F5: EFT_INSTANT | G5: GW-000004 | H5: SUCCESS
A6: D000005 | B6: P0008 | C6: 2026-09-01 02:42:07 | D6: 500 | E6: NAD | F6: EFT_INSTANT | G6: GW-000005 | H6: SUCCESS
A7: D000321 | B7: P0078 | C7: 2026-09-01 03:11:39 | D7: 100 | E7: NAD | F7: EFT_INSTANT | G7: GW-000321 | H7: FAILED
A8: D000006 | B8: P0004 | C8: 2026-09-01 03:20:46 | D8: 1500 | E8: NAD | F8: EFT_INSTANT | G8: GW-000006 | H8: SUCCESS
A9: D000007 | B9: P0038 | C9: 2026-09-01 04:02:24 | D9: 500 | E9: NAD | F9: EFT_INSTANT | G9: GW-000007 | H9: SUCCESS
A10: D000008 | B10: P0039 | C10: 2026-09-01 04:05:14 | D10: 100 | E10: NAD | F10: EFT_INSTANT | G10: GW-000008 | H10: SUCCESS
A11: D000009 | B11: P0041 | C11: 2026-09-01 04:06:58 | D11: 1500 | E11: NAD | F11: EFT_INSTANT | G11: GW-000009 | H11: SUCCESS
A12: D000010 | B12: P0070 | C12: 2026-09-01 04:29:39 | D12: 20 | E12: NAD | F12: EFT_INSTANT | G12: GW-000010 | H12: SUCCESS
A13: D000011 | B13: P0072 | C13: 2026-09-01 05:57:44 | D13: 150 | E13: NAD | F13: EFT_INSTANT | G13: GW-000011 | H13: SUCCESS
... A327: D000330 | B327: P0076 | C327: 2026-09-07 23:55:00 | D327: 150 | E327: NAD | F327: EFT_INSTANT | G327: GW-000330 | H327: SUCCESS

Sheet Gateway settlement
A1: gateway_txn_id | B1: merchant_ref | C1: settled_at | D1: gross_amount | E1: fee | F1: net_amount | G1: currency | H1: status
A2: GT900331 | B2: GW-000331 | C2: 2026-09-01 00:04:00 | D2: 2000 | E2: 41 | F2: 1959 | G2: NAD | H2: SETTLED
A3: GT900332 | B3: GW-000332 | C3: 2026-09-01 00:05:00 | D3: 100 | E3: 3 | F3: 97 | G3: NAD | H3: SETTLED
A4: GT900333 | B4: GW-000333 | C4: 2026-09-01 00:06:00 | D4: 500 | E4: 11 | F4: 489 | G4: NAD | H4: SETTLED
A5: GT900001 | B5: GW-000001 | C5: 2026-09-01 00:33:44 | D5: 150 | E5: 4 | F5: 146 | G5: NAD | H5: SETTLED
A6: GT900002 | B6: GW-000002 | C6: 2026-09-01 00:52:17 | D6: 1500 | E6: 31 | F6: 1469 | G6: NAD | H6: SETTLED
A7: GT900004 | B7: GW-000004 | C7: 2026-09-01 01:48:40 | D7: 250 | E7: 6 | F7: 244 | G7: NAD | H7: SETTLED
A8: GT900302 | B8: GW-000302 | C8: 2026-09-01 02:00:06 | D8: 100 | E8: 3 | F8: 97 | G8: NAD | H8: SETTLED
A9: GT900003 | B9: GW-000003 | C9: 2026-09-01 02:09:44 | D9: 500 | E9: 11 | F9: 489 | G9: NAD | H9: SETTLED
A10: GT900005 | B10: GW-000005 | C10: 2026-09-01 03:30:07 | D10: 500 | E10: 11 | F10: 489 | G10: NAD | H10: SETTLED
A11: GT900006 | B11: GW-000006 | C11: 2026-09-01 03:39:46 | D11: 1500 | E11: 31 | F11: 1469 | G11: NAD | H11: SETTLED
A12: GT900009 | B12: GW-000009 | C12: 2026-09-01 04:44:58 | D12: 1500 | E12: 31 | F12: 1469 | G12: NAD | H12: SETTLED
A13: GT900007 | B13: GW-000007 | C13: 2026-09-01 04:49:24 | D13: 500 | E13: 11 | F13: 489 | G13: NAD | H13: SETTLED
... A307: GT900299 | B307: GW-000299 | C307: 2026-09-07 23:14:13 | D307: 150 | E307: 4 | F307: 146 | G307: NAD | H307: SETTLED
